<?xml version="1.0"?>
<robot name="robot_core" xmlns:xacro="http://www.ros.org/wiki/xacro">

  <!-- Define color -->
  <material name="yellow">
    <color rgba="1 1 0 1"/>
  </material>
  <material name="black">
    <color rgba="0 0 0 1"/>
  </material>

  <!-- Define the base link -->
  <link name="base_link">
    <visual>
      <geometry>
        <cylinder radius="0.1815" length="0.01"/> <!-- Base plate dimensions -->
      </geometry>
      <material name="yellow"/>
      <origin xyz="0 0 0.005" rpy="0 0 0"/>
    </visual>
    <collision>
      <geometry>
        <cylinder radius="0.1815" length="0.01"/> <!-- Base plate dimensions -->
      </geometry>
      <origin xyz="0 0 0.005" rpy="0 0 0"/>
    </collision>
    <inertial>
      <mass value="1"/> <!-- Adjust mass as needed -->
      <origin xyz="0 0 0.005"/>
      <inertia ixx="0.01" ixy="0.0" ixz="0.0"
               iyy="0.01" iyz="0.0"
               izz="0.01"/> <!-- Approximate inertia values -->
    </inertial>
  </link>

  <!-- Define the chassis link -->
  <link name="chassis_link">
    <visual>
      <geometry>
        <cylinder radius="0.1815" length="0.25"/> <!-- 363mm diameter, 250mm height -->
      </geometry>
      <material name="yellow"/>
      <origin xyz="0 0 0.125" rpy="0 0 0"/> <!-- Centered on the base -->
    </visual>
    <collision>
      <geometry>
        <cylinder radius="0.1815" length="0.25"/>
      </geometry>
      <origin xyz="0 0 0.125" rpy="0 0 0"/>
    </collision>
    <inertial>
      <mass value="5"/> <!-- Adjust mass as needed -->
      <origin xyz="0 0 0.125"/>
      <inertia ixx="0.1" ixy="0.0" ixz="0.0"
               iyy="0.1" iyz="0.0"
               izz="0.1"/> <!-- Approximate inertia values -->
    </inertial>
  </link>

  <!-- Joint between base_link and chassis_link -->
  <joint name="base_to_chassis" type="fixed">
    <parent link="base_link"/>
    <child link="chassis_link"/>
    <origin xyz="0 0 0.005" rpy="0 0 0"/> <!-- Adjust based on actual height -->
  </joint>

  <!-- Left wheel -->
  <joint name="left_wheel_joint" type="continuous">
    <parent link="base_link"/>
    <child link="left_wheel"/>
    <origin xyz="0 0.195 0" rpy="-1.5708 0 0"/> <!-- Adjusted to numerical value -->
    <axis xyz="0 0 1"/>
  </joint>

  <link name="left_wheel">
    <visual> 
      <geometry>
        <cylinder radius="0.05" length="0.04"/>
      </geometry>
      <material name="black"/>
    </visual>
    <collision> 
      <geometry>
        <cylinder radius="0.05" length="0.04"/>
      </geometry>
    </collision>
    <inertial>
      <mass value="0.1"/> <!-- Adjust mass as needed -->
      <origin xyz="0 0 0"/>
      <inertia ixx="0.0001" ixy="0.0" ixz="0.0"
               iyy="0.0001" iyz="0.0"
               izz="0.0001"/> <!-- Approximate inertia values -->
    </inertial>
  </link>

  <!-- Right wheel -->
  <joint name="right_wheel_joint" type="continuous">
    <parent link="base_link"/>
    <child link="right_wheel"/>
    <origin xyz="0 -0.195 0" rpy="1.5708 0 0"/> <!-- Adjusted to numerical value -->
    <axis xyz="0 0 -1"/>
  </joint>

  <link name="right_wheel">
    <visual> 
      <geometry>
        <cylinder radius="0.05" length="0.04"/>
      </geometry>
      <material name="black"/>
    </visual>
    <collision> 
      <geometry>
        <cylinder radius="0.05" length="0.04"/>
      </geometry>
    </collision>
    <inertial>
      <mass value="0.1"/> <!-- Adjust mass as needed -->
      <origin xyz="0 0 0"/>
      <inertia ixx="0.0001" ixy="0.0" ixz="0.0"
               iyy="0.0001" iyz="0.0"
               izz="0.0001"/> <!-- Approximate inertia values -->
    </inertial>
  </link>

  <!-- Caster wheel front -->
  <joint name="caster_wheel_joint_front" type="fixed">
    <parent link="base_link"/>
    <child link="caster_wheel_front"/>
    <origin xyz="0.12 0 0"/> <!-- Adjusted based on position -->
  </joint>

  <link name="caster_wheel_front">
    <visual>
      <geometry>
        <sphere radius="0.05"/>
      </geometry>
      <material name="black"/>
    </visual>
    <collision>
      <geometry>
        <sphere radius="0.05"/>
      </geometry>
    </collision>
    <inertial>
      <mass value="0.1"/> <!-- Adjust mass as needed -->
      <origin xyz="0 0 0"/>
      <inertia ixx="0.0001" ixy="0.0" ixz="0.0"
               iyy="0.0001" iyz="0.0"
               izz="0.0001"/> <!-- Approximate inertia values -->
    </inertial>
  </link>

  <!-- Caster wheel back -->
  <joint name="caster_wheel_joint_back" type="fixed">
    <parent link="base_link"/>
    <child link="caster_wheel_back"/>
    <origin xyz="-0.12 0 0"/> <!-- Adjusted based on position -->
  </joint>

  <link name="caster_wheel_back">
    <visual>
      <geometry>
        <sphere radius="0.05"/>
      </geometry>
      <material name="black"/>
    </visual>
    <collision>
      <geometry>
        <sphere radius="0.05"/>
      </geometry>
    </collision>
    <inertial>
      <mass value="0.1"/> <!-- Adjust mass as needed -->
      <origin xyz="0 0 0"/>
      <inertia ixx="0.0001" ixy="0.0" ixz="0.0"
               iyy="0.0001" iyz="0.0"
               izz="0.0001"/> <!-- Approximate inertia values -->
    </inertial>
  </link>

</robot>
